2019-01-05 21:21:29,728 ERROR: Exception on /users/signup [GET] [in c:\users\rohit\envs\shopnow\lib\site-packages\flask\app.py:1761]
Traceback (most recent call last):
  File "c:\users\rohit\envs\shopnow\lib\site-packages\flask\app.py", line 2292, in wsgi_app
    response = self.full_dispatch_request()
  File "c:\users\rohit\envs\shopnow\lib\site-packages\flask\app.py", line 1815, in full_dispatch_request
    rv = self.handle_user_exception(e)
  File "c:\users\rohit\envs\shopnow\lib\site-packages\flask\app.py", line 1718, in handle_user_exception
    reraise(exc_type, exc_value, tb)
  File "c:\users\rohit\envs\shopnow\lib\site-packages\flask\_compat.py", line 35, in reraise
    raise value
  File "c:\users\rohit\envs\shopnow\lib\site-packages\flask\app.py", line 1813, in full_dispatch_request
    rv = self.dispatch_request()
  File "c:\users\rohit\envs\shopnow\lib\site-packages\flask\app.py", line 1799, in dispatch_request
    return self.view_functions[rule.endpoint](**req.view_args)
  File "C:\Users\Rohit\DEV\ShopNow\app\users\routes.py", line 10, in signUp
    if(not(current_user.is_anonymous())):
TypeError: 'bool' object is not callable
2019-01-05 21:21:34,473 ERROR: Exception on /users/signup [GET] [in c:\users\rohit\envs\shopnow\lib\site-packages\flask\app.py:1761]
Traceback (most recent call last):
  File "c:\users\rohit\envs\shopnow\lib\site-packages\flask\app.py", line 2292, in wsgi_app
    response = self.full_dispatch_request()
  File "c:\users\rohit\envs\shopnow\lib\site-packages\flask\app.py", line 1815, in full_dispatch_request
    rv = self.handle_user_exception(e)
  File "c:\users\rohit\envs\shopnow\lib\site-packages\flask\app.py", line 1718, in handle_user_exception
    reraise(exc_type, exc_value, tb)
  File "c:\users\rohit\envs\shopnow\lib\site-packages\flask\_compat.py", line 35, in reraise
    raise value
  File "c:\users\rohit\envs\shopnow\lib\site-packages\flask\app.py", line 1813, in full_dispatch_request
    rv = self.dispatch_request()
  File "c:\users\rohit\envs\shopnow\lib\site-packages\flask\app.py", line 1799, in dispatch_request
    return self.view_functions[rule.endpoint](**req.view_args)
  File "C:\Users\Rohit\DEV\ShopNow\app\users\routes.py", line 10, in signUp
    if(not(current_user.is_anonymous())):
TypeError: 'bool' object is not callable
2019-01-05 21:22:17,299 INFO: ShopNow Startup [in C:\Users\Rohit\DEV\ShopNow\app\__init__.py:54]
2019-01-05 21:22:19,998 ERROR: Exception on /users/signup [GET] [in c:\users\rohit\envs\shopnow\lib\site-packages\flask\app.py:1761]
Traceback (most recent call last):
  File "c:\users\rohit\envs\shopnow\lib\site-packages\flask\app.py", line 2292, in wsgi_app
    response = self.full_dispatch_request()
  File "c:\users\rohit\envs\shopnow\lib\site-packages\flask\app.py", line 1815, in full_dispatch_request
    rv = self.handle_user_exception(e)
  File "c:\users\rohit\envs\shopnow\lib\site-packages\flask\app.py", line 1718, in handle_user_exception
    reraise(exc_type, exc_value, tb)
  File "c:\users\rohit\envs\shopnow\lib\site-packages\flask\_compat.py", line 35, in reraise
    raise value
  File "c:\users\rohit\envs\shopnow\lib\site-packages\flask\app.py", line 1813, in full_dispatch_request
    rv = self.dispatch_request()
  File "c:\users\rohit\envs\shopnow\lib\site-packages\flask\app.py", line 1799, in dispatch_request
    return self.view_functions[rule.endpoint](**req.view_args)
  File "C:\Users\Rohit\DEV\ShopNow\app\users\routes.py", line 10, in signUp
    if(not(current_user.is_anonymous())):
TypeError: 'bool' object is not callable
2019-01-05 21:22:22,287 ERROR: Exception on /users/signup [GET] [in c:\users\rohit\envs\shopnow\lib\site-packages\flask\app.py:1761]
Traceback (most recent call last):
  File "c:\users\rohit\envs\shopnow\lib\site-packages\flask\app.py", line 2292, in wsgi_app
    response = self.full_dispatch_request()
  File "c:\users\rohit\envs\shopnow\lib\site-packages\flask\app.py", line 1815, in full_dispatch_request
    rv = self.handle_user_exception(e)
  File "c:\users\rohit\envs\shopnow\lib\site-packages\flask\app.py", line 1718, in handle_user_exception
    reraise(exc_type, exc_value, tb)
  File "c:\users\rohit\envs\shopnow\lib\site-packages\flask\_compat.py", line 35, in reraise
    raise value
  File "c:\users\rohit\envs\shopnow\lib\site-packages\flask\app.py", line 1813, in full_dispatch_request
    rv = self.dispatch_request()
  File "c:\users\rohit\envs\shopnow\lib\site-packages\flask\app.py", line 1799, in dispatch_request
    return self.view_functions[rule.endpoint](**req.view_args)
  File "C:\Users\Rohit\DEV\ShopNow\app\users\routes.py", line 10, in signUp
    if(not(current_user.is_anonymous())):
TypeError: 'bool' object is not callable
2019-01-05 21:22:42,381 INFO: ShopNow Startup [in C:\Users\Rohit\DEV\ShopNow\app\__init__.py:54]
2019-01-05 21:23:12,793 INFO: ShopNow Startup [in C:\Users\Rohit\DEV\ShopNow\app\__init__.py:54]
2019-01-05 21:23:38,565 INFO: ShopNow Startup [in C:\Users\Rohit\DEV\ShopNow\app\__init__.py:54]
2019-01-05 21:26:31,018 INFO: ShopNow Startup [in C:\Users\Rohit\DEV\ShopNow\app\__init__.py:54]
2019-01-05 21:26:46,234 ERROR: Exception on /users/updatepassword [GET] [in c:\users\rohit\envs\shopnow\lib\site-packages\flask\app.py:1761]
Traceback (most recent call last):
  File "c:\users\rohit\envs\shopnow\lib\site-packages\flask\app.py", line 2292, in wsgi_app
    response = self.full_dispatch_request()
  File "c:\users\rohit\envs\shopnow\lib\site-packages\flask\app.py", line 1815, in full_dispatch_request
    rv = self.handle_user_exception(e)
  File "c:\users\rohit\envs\shopnow\lib\site-packages\flask\app.py", line 1718, in handle_user_exception
    reraise(exc_type, exc_value, tb)
  File "c:\users\rohit\envs\shopnow\lib\site-packages\flask\_compat.py", line 35, in reraise
    raise value
  File "c:\users\rohit\envs\shopnow\lib\site-packages\flask\app.py", line 1813, in full_dispatch_request
    rv = self.dispatch_request()
  File "c:\users\rohit\envs\shopnow\lib\site-packages\flask\app.py", line 1799, in dispatch_request
    return self.view_functions[rule.endpoint](**req.view_args)
  File "c:\users\rohit\envs\shopnow\lib\site-packages\flask_login\utils.py", line 261, in decorated_view
    return func(*args, **kwargs)
  File "C:\Users\Rohit\DEV\ShopNow\app\users\routes.py", line 34, in updatePassword
    return(render_template('updatepassword.html', title='Update User Details', form=form))
  File "c:\users\rohit\envs\shopnow\lib\site-packages\flask\templating.py", line 134, in render_template
    return _render(ctx.app.jinja_env.get_or_select_template(template_name_or_list),
  File "c:\users\rohit\envs\shopnow\lib\site-packages\jinja2\environment.py", line 869, in get_or_select_template
    return self.get_template(template_name_or_list, parent, globals)
  File "c:\users\rohit\envs\shopnow\lib\site-packages\jinja2\environment.py", line 830, in get_template
    return self._load_template(name, self.make_globals(globals))
  File "c:\users\rohit\envs\shopnow\lib\site-packages\jinja2\environment.py", line 804, in _load_template
    template = self.loader.load(self, name, globals)
  File "c:\users\rohit\envs\shopnow\lib\site-packages\jinja2\loaders.py", line 113, in load
    source, filename, uptodate = self.get_source(environment, name)
  File "c:\users\rohit\envs\shopnow\lib\site-packages\flask\templating.py", line 58, in get_source
    return self._get_source_fast(environment, template)
  File "c:\users\rohit\envs\shopnow\lib\site-packages\flask\templating.py", line 86, in _get_source_fast
    raise TemplateNotFound(template)
jinja2.exceptions.TemplateNotFound: updatepassword.html
2019-01-05 21:27:34,989 INFO: ShopNow Startup [in C:\Users\Rohit\DEV\ShopNow\app\__init__.py:54]
