2019-01-05 17:13:35,649 ERROR: Exception on / [GET] [in c:\users\rohit\envs\shopnow\lib\site-packages\flask\app.py:1761]
Traceback (most recent call last):
  File "c:\users\rohit\envs\shopnow\lib\site-packages\flask\app.py", line 2292, in wsgi_app
    response = self.full_dispatch_request()
  File "c:\users\rohit\envs\shopnow\lib\site-packages\flask\app.py", line 1815, in full_dispatch_request
    rv = self.handle_user_exception(e)
  File "c:\users\rohit\envs\shopnow\lib\site-packages\flask\app.py", line 1718, in handle_user_exception
    reraise(exc_type, exc_value, tb)
  File "c:\users\rohit\envs\shopnow\lib\site-packages\flask\_compat.py", line 35, in reraise
    raise value
  File "c:\users\rohit\envs\shopnow\lib\site-packages\flask\app.py", line 1813, in full_dispatch_request
    rv = self.dispatch_request()
  File "c:\users\rohit\envs\shopnow\lib\site-packages\flask\app.py", line 1799, in dispatch_request
    return self.view_functions[rule.endpoint](**req.view_args)
  File "c:\users\rohit\envs\shopnow\lib\site-packages\flask_login\utils.py", line 260, in decorated_view
    return current_app.login_manager.unauthorized()
  File "c:\users\rohit\envs\shopnow\lib\site-packages\flask_login\login_manager.py", line 175, in unauthorized
    redirect_url = make_login_url(login_view, next_url=request.url)
  File "c:\users\rohit\envs\shopnow\lib\site-packages\flask_login\utils.py", line 112, in login_url
    base = expand_login_view(login_view)
  File "c:\users\rohit\envs\shopnow\lib\site-packages\flask_login\utils.py", line 89, in expand_login_view
    return url_for(login_view)
  File "c:\users\rohit\envs\shopnow\lib\site-packages\flask\helpers.py", line 356, in url_for
    return appctx.app.handle_url_build_error(error, endpoint, values)
  File "c:\users\rohit\envs\shopnow\lib\site-packages\flask\app.py", line 2061, in handle_url_build_error
    reraise(exc_type, exc_value, tb)
  File "c:\users\rohit\envs\shopnow\lib\site-packages\flask\_compat.py", line 35, in reraise
    raise value
  File "c:\users\rohit\envs\shopnow\lib\site-packages\flask\helpers.py", line 345, in url_for
    force_external=external)
  File "c:\users\rohit\envs\shopnow\lib\site-packages\werkzeug\routing.py", line 1776, in build
    raise BuildError(endpoint, values, method, self)
werkzeug.routing.BuildError: Could not build url for endpoint 'logIn'. Did you mean 'index' instead?
2019-01-05 17:14:21,770 INFO: ShopNow Startup [in C:\Users\Rohit\DEV\ShopNow\app\__init__.py:25]
2019-01-05 17:14:25,034 ERROR: Exception on / [GET] [in c:\users\rohit\envs\shopnow\lib\site-packages\flask\app.py:1761]
Traceback (most recent call last):
  File "c:\users\rohit\envs\shopnow\lib\site-packages\flask\app.py", line 2292, in wsgi_app
    response = self.full_dispatch_request()
  File "c:\users\rohit\envs\shopnow\lib\site-packages\flask\app.py", line 1815, in full_dispatch_request
    rv = self.handle_user_exception(e)
  File "c:\users\rohit\envs\shopnow\lib\site-packages\flask\app.py", line 1718, in handle_user_exception
    reraise(exc_type, exc_value, tb)
  File "c:\users\rohit\envs\shopnow\lib\site-packages\flask\_compat.py", line 35, in reraise
    raise value
  File "c:\users\rohit\envs\shopnow\lib\site-packages\flask\app.py", line 1813, in full_dispatch_request
    rv = self.dispatch_request()
  File "c:\users\rohit\envs\shopnow\lib\site-packages\flask\app.py", line 1799, in dispatch_request
    return self.view_functions[rule.endpoint](**req.view_args)
  File "c:\users\rohit\envs\shopnow\lib\site-packages\flask_login\utils.py", line 260, in decorated_view
    return current_app.login_manager.unauthorized()
  File "c:\users\rohit\envs\shopnow\lib\site-packages\flask_login\login_manager.py", line 175, in unauthorized
    redirect_url = make_login_url(login_view, next_url=request.url)
  File "c:\users\rohit\envs\shopnow\lib\site-packages\flask_login\utils.py", line 112, in login_url
    base = expand_login_view(login_view)
  File "c:\users\rohit\envs\shopnow\lib\site-packages\flask_login\utils.py", line 89, in expand_login_view
    return url_for(login_view)
  File "c:\users\rohit\envs\shopnow\lib\site-packages\flask\helpers.py", line 356, in url_for
    return appctx.app.handle_url_build_error(error, endpoint, values)
  File "c:\users\rohit\envs\shopnow\lib\site-packages\flask\app.py", line 2061, in handle_url_build_error
    reraise(exc_type, exc_value, tb)
  File "c:\users\rohit\envs\shopnow\lib\site-packages\flask\_compat.py", line 35, in reraise
    raise value
  File "c:\users\rohit\envs\shopnow\lib\site-packages\flask\helpers.py", line 345, in url_for
    force_external=external)
  File "c:\users\rohit\envs\shopnow\lib\site-packages\werkzeug\routing.py", line 1776, in build
    raise BuildError(endpoint, values, method, self)
werkzeug.routing.BuildError: Could not build url for endpoint 'logIn'. Did you mean 'auth.logIn' instead?
2019-01-05 17:15:18,350 ERROR: Exception on / [GET] [in c:\users\rohit\envs\shopnow\lib\site-packages\flask\app.py:1761]
Traceback (most recent call last):
  File "c:\users\rohit\envs\shopnow\lib\site-packages\flask\app.py", line 2292, in wsgi_app
    response = self.full_dispatch_request()
  File "c:\users\rohit\envs\shopnow\lib\site-packages\flask\app.py", line 1815, in full_dispatch_request
    rv = self.handle_user_exception(e)
  File "c:\users\rohit\envs\shopnow\lib\site-packages\flask\app.py", line 1718, in handle_user_exception
    reraise(exc_type, exc_value, tb)
  File "c:\users\rohit\envs\shopnow\lib\site-packages\flask\_compat.py", line 35, in reraise
    raise value
  File "c:\users\rohit\envs\shopnow\lib\site-packages\flask\app.py", line 1813, in full_dispatch_request
    rv = self.dispatch_request()
  File "c:\users\rohit\envs\shopnow\lib\site-packages\flask\app.py", line 1799, in dispatch_request
    return self.view_functions[rule.endpoint](**req.view_args)
  File "c:\users\rohit\envs\shopnow\lib\site-packages\flask_login\utils.py", line 260, in decorated_view
    return current_app.login_manager.unauthorized()
  File "c:\users\rohit\envs\shopnow\lib\site-packages\flask_login\login_manager.py", line 175, in unauthorized
    redirect_url = make_login_url(login_view, next_url=request.url)
  File "c:\users\rohit\envs\shopnow\lib\site-packages\flask_login\utils.py", line 112, in login_url
    base = expand_login_view(login_view)
  File "c:\users\rohit\envs\shopnow\lib\site-packages\flask_login\utils.py", line 89, in expand_login_view
    return url_for(login_view)
  File "c:\users\rohit\envs\shopnow\lib\site-packages\flask\helpers.py", line 356, in url_for
    return appctx.app.handle_url_build_error(error, endpoint, values)
  File "c:\users\rohit\envs\shopnow\lib\site-packages\flask\app.py", line 2061, in handle_url_build_error
    reraise(exc_type, exc_value, tb)
  File "c:\users\rohit\envs\shopnow\lib\site-packages\flask\_compat.py", line 35, in reraise
    raise value
  File "c:\users\rohit\envs\shopnow\lib\site-packages\flask\helpers.py", line 345, in url_for
    force_external=external)
  File "c:\users\rohit\envs\shopnow\lib\site-packages\werkzeug\routing.py", line 1776, in build
    raise BuildError(endpoint, values, method, self)
werkzeug.routing.BuildError: Could not build url for endpoint 'logIn'. Did you mean 'auth.logIn' instead?
2019-01-05 17:15:19,654 ERROR: Exception on / [GET] [in c:\users\rohit\envs\shopnow\lib\site-packages\flask\app.py:1761]
Traceback (most recent call last):
  File "c:\users\rohit\envs\shopnow\lib\site-packages\flask\app.py", line 2292, in wsgi_app
    response = self.full_dispatch_request()
  File "c:\users\rohit\envs\shopnow\lib\site-packages\flask\app.py", line 1815, in full_dispatch_request
    rv = self.handle_user_exception(e)
  File "c:\users\rohit\envs\shopnow\lib\site-packages\flask\app.py", line 1718, in handle_user_exception
    reraise(exc_type, exc_value, tb)
  File "c:\users\rohit\envs\shopnow\lib\site-packages\flask\_compat.py", line 35, in reraise
    raise value
  File "c:\users\rohit\envs\shopnow\lib\site-packages\flask\app.py", line 1813, in full_dispatch_request
    rv = self.dispatch_request()
  File "c:\users\rohit\envs\shopnow\lib\site-packages\flask\app.py", line 1799, in dispatch_request
    return self.view_functions[rule.endpoint](**req.view_args)
  File "c:\users\rohit\envs\shopnow\lib\site-packages\flask_login\utils.py", line 260, in decorated_view
    return current_app.login_manager.unauthorized()
  File "c:\users\rohit\envs\shopnow\lib\site-packages\flask_login\login_manager.py", line 175, in unauthorized
    redirect_url = make_login_url(login_view, next_url=request.url)
  File "c:\users\rohit\envs\shopnow\lib\site-packages\flask_login\utils.py", line 112, in login_url
    base = expand_login_view(login_view)
  File "c:\users\rohit\envs\shopnow\lib\site-packages\flask_login\utils.py", line 89, in expand_login_view
    return url_for(login_view)
  File "c:\users\rohit\envs\shopnow\lib\site-packages\flask\helpers.py", line 356, in url_for
    return appctx.app.handle_url_build_error(error, endpoint, values)
  File "c:\users\rohit\envs\shopnow\lib\site-packages\flask\app.py", line 2061, in handle_url_build_error
    reraise(exc_type, exc_value, tb)
  File "c:\users\rohit\envs\shopnow\lib\site-packages\flask\_compat.py", line 35, in reraise
    raise value
  File "c:\users\rohit\envs\shopnow\lib\site-packages\flask\helpers.py", line 345, in url_for
    force_external=external)
  File "c:\users\rohit\envs\shopnow\lib\site-packages\werkzeug\routing.py", line 1776, in build
    raise BuildError(endpoint, values, method, self)
werkzeug.routing.BuildError: Could not build url for endpoint 'logIn'. Did you mean 'auth.logIn' instead?
2019-01-05 17:15:24,791 INFO: ShopNow Startup [in C:\Users\Rohit\DEV\ShopNow\app\__init__.py:25]
